<mujoco model="X02Lite">
  <compiler angle="radian" meshdir="meshes/" autolimits="true"/>
  <size njmax="500" nconmax="100" />
  <option timestep='0.001' iterations='50' solver='PGS' gravity='0 0 -9.81'>
  <flag   contact="enable" energy="enable" gravity="enable"/>
  </option>
  <visual>
    <quality shadowsize='4096'/>
    <map znear='0.05'/>
  </visual>
  <default>
    <geom contype='0' conaffinity='0' condim='1'/>  <!--默认完全无碰撞摩擦-->
    <default class='collision'>
      <geom material='collision' contype='1'/>   <!--collision：只与地面碰撞摩擦-->
      <default class='collision-left'>
        <geom condim='1' contype='4' conaffinity='2'/>  <!--collision-left：与地面、右腿碰撞摩擦-->
      </default>
      <default class='collision-right'>
        <geom condim='1' contype='2' conaffinity='4'/>  <!--collision-right：与地面、左腿碰撞摩擦-->
      </default>
    </default>
  </default>
  <asset>
    <texture type='skybox' builtin='gradient' width='128' height='128' rgb1='0.4 0.6 0.8' rgb2='0 0 0'/>
    <texture name='plane' type='2d' builtin='checker' rgb1='0.6 0.6 0.6' rgb2='0.8 0.8 0.8' width='512' height='512'/>
    <material name='plane' reflectance='0.0' texture='plane' texrepeat='1 1' texuniform='true'/>
    <material name='collision' rgba='0.1 0.5 0.9 0'/> <!--collision rgba 无颜色-->
    <mesh name="pelvis" file="pelvis.STL"/>
    <mesh name="torso_Link" file="torso_link.STL"/>
    <mesh name="L_shoulder_pitch_Link" file="L_shoulder_pitch_Link.STL"/>
    <mesh name="L_shoulder_roll_Link" file="L_shoulder_roll_Link.STL"/>
    <mesh name="L_shoulder_yaw_Link" file="L_shoulder_yaw_Link.STL"/>
    <mesh name="L_elbow_Link" file="L_elbow_Link.STL"/>
    <mesh name="R_shoulder_pitch_Link" file="R_shoulder_pitch_Link.STL"/>
    <mesh name="R_shoulder_roll_Link" file="R_shoulder_roll_Link.STL"/>
    <mesh name="R_shoulder_yaw_Link" file="R_shoulder_yaw_Link.STL"/>
    <mesh name="R_elbow_Link" file="R_elbow_Link.STL"/>
    <mesh name="Head_Link" file="Head_Link.STL"/>
    <mesh name="Logo_Link" file="Logo_Link.STL"/>
    <mesh name="L_hip_yaw_Link" file="L_hip_yaw_Link.STL"/>
    <mesh name="L_hip_roll_Link" file="L_hip_roll_Link.STL"/>
    <mesh name="L_hip_pitch_Link" file="L_hip_pitch_Link.STL"/>
    <mesh name="L_knee_Link" file="L_knee_Link.STL"/>
    <mesh name="L_ankle_pitch_Link" file="L_ankle_pitch_Link.STL"/>
    <mesh name="R_hip_yaw_Link" file="R_hip_yaw_Link.STL"/>
    <mesh name="R_hip_roll_Link" file="R_hip_roll_Link.STL"/>
    <mesh name="R_hip_pitch_Link" file="R_hip_pitch_Link.STL"/>
    <mesh name="R_knee_Link" file="R_knee_Link.STL"/>
    <mesh name="R_ankle_pitch_Link" file="R_ankle_pitch_Link.STL"/>
  </asset>

  <worldbody>
    <geom name='wp' pos='0 0 0' size='0 0 0.1' type='plane' material='plane' contype="0" conaffinity="15" condim='3'/>
    <light mode='trackcom' pos='0 0 5' dir='0 0 -1'/>
    <light directional='true' pos='0 0 3' dir='0 0 -1' diffuse='0.2 0.2 0.2' specular='0 0 0'/>
    <body name="pelvis" pos="0. 0. 0.962">
      <inertial pos="0.00368859 0.000469457 0.20791" quat="0.999947 -0.000638702 0.00912233 -0.00471769" mass="11.0225" diaginertia="0.284285 0.255222 0.0799245"/>
      <joint name="pelvis" type="free" limited="false" />
      <geom type="mesh" contype="0" conaffinity="0" group="1" density="0" rgba="1 1 1 1" mesh="pelvis"/>
      <geom type="mesh" contype="0" conaffinity="0" group="1" density="0" rgba="1 1 1 1" mesh="torso_Link"/>
      <geom pos="0 0 0.355" quat="1 0 0 0" type="mesh" contype="0" conaffinity="0" group="1" density="0" rgba="0.2 0.2 0.2 0.9" mesh="Head_Link"/>
      <geom type="mesh" contype="0" conaffinity="0" group="1" density="0" rgba="1 0 0 0.8" mesh="Logo_Link"/>
      <site name="imu" pos="0 0 0.17"/>
      <body name="L_shoulder_pitch_Link" pos="0 0.136079 0.306812" quat="0.560986 -0.430459 0.430459 0.560986">
        <inertial pos="0.000994 0.000135 0.015061" quat="0.999951 0.00142838 -0.00973082 -0.000916417" mass="0.3" diaginertia="0.000621668 0.000564559 0.00017063"/>
<!--        <joint name="L_shoulder_pitch" pos="0 0 0" axis="0 0 -1" range="-1.5708 3.14159" actuatorfrcrange="-18 18"/>-->
        <geom type="mesh" contype="0" conaffinity="0" group="1" density="0" rgba="0.2 0.2 0.2 0.9" mesh="L_shoulder_pitch_Link"/>
        <body name="L_shoulder_roll_Link" pos="0 0 0.061" quat="0.701057 -0.701057 0.092296 0.092296">
          <inertial pos="0.043319 -0.000273 5.6e-05" quat="0.498871 0.497768 0.499964 0.50338" mass="0.704" diaginertia="0.00150267 0.00145041 0.0002954"/>
<!--          <joint name="L_shoulder_roll" pos="0 0 0" axis="0 0 -1" range="0 3.14159" actuatorfrcrange="-14 14"/>-->
          <geom type="mesh" contype="0" conaffinity="0" group="1" density="0" rgba="1 1 1 1" mesh="L_shoulder_roll_Link"/>
          <body name="L_shoulder_yaw_Link" pos="0.112 0 0" quat="0.5 0.5 0.5 0.5">
            <inertial pos="0.00023 -0.00433 0.132049" quat="0.708733 -0.0285968 0.02696 0.704381" mass="0.523" diaginertia="0.0020845 0.00203369 0.000281981"/>
<!--            <joint name="L_shoulder_yaw" pos="0 0 0" axis="0 0 -1" range="-2.26893 2.26893" actuatorfrcrange="-14 14"/>-->
            <geom type="mesh" contype="0" conaffinity="0" group="1" density="0" rgba="0.2 0.2 0.2 0.9" mesh="L_shoulder_yaw_Link"/>
            <body name="L_elbow_Link" pos="0 -0.01 0.173" quat="-0.500000 0.500000 -0.500000 0.500000" >
              <inertial pos="0.032629 -0.007406 0.000107" quat="0.48876 0.493594 0.505647 0.511664" mass="0.24" diaginertia="0.00105837 0.001019 0.000141685"/>
<!--              <joint name="L_elbow" pos="0 0 0" axis="0 0 1" range="0 2.53073" actuatorfrcrange="-14 14"/>-->
              <geom type="mesh" contype="0" conaffinity="0" group="1" density="0" rgba="1 1 1 1" mesh="L_elbow_Link"/>
            </body>
          </body>
        </body>
      </body>
      <body name="R_shoulder_pitch_Link" pos="0 -0.136079 0.306812" quat="0.560986 0.430459 0.430459 -0.560986">
        <inertial pos="0.000994 -0.000135 0.015061" quat="0.999951 -0.0014286 -0.00973075 0.00093389" mass="0.3" diaginertia="0.000621667 0.000564556 0.000170627"/>
<!--        <joint name="R_shoulder_pitch" pos="0 0 0" axis="0 0 1" range="-1.5708 3.14159" actuatorfrcrange="-18 18"/>-->
        <geom type="mesh" contype="0" conaffinity="0" group="1" density="0" rgba="0.2 0.2 0.2 0.9" mesh="R_shoulder_pitch_Link"/>
        <body name="R_shoulder_roll_Link" pos="0 0 0.061" quat="0.701057 -0.701057 0.092296 0.092296">
          <inertial pos="0.043319 -0.000273 5.6e-05" quat="0.496954 0.499689 0.502568 0.500773" mass="0.704" diaginertia="0.00150267 0.00145041 0.0002954"/>
<!--          <joint name="R_shoulder_roll" pos="0 0 0" axis="0 0 -1" range="0 3.14159" actuatorfrcrange="-14 14"/>-->
          <geom type="mesh" contype="0" conaffinity="0" group="1" density="0" rgba="1 1 1 1" mesh="R_shoulder_roll_Link"/>
          <body name="R_shoulder_yaw_Link" pos="0.112 0 0" quat="0.5 0.5 0.5 0.5">
            <inertial pos="0.00023 0.00433 0.132049" quat="0.712686 0.0273141 -0.0282578 0.700381" mass="0.523" diaginertia="0.00208452 0.00203368 0.000281981"/>
<!--            <joint name="R_shoulder_yaw" pos="0 0 0" axis="0 0 1" range="-2.26893 2.26893" actuatorfrcrange="-14 14"/>-->
            <geom type="mesh" contype="0" conaffinity="0" group="1" density="0" rgba="0.2 0.2 0.2 0.9" mesh="R_shoulder_yaw_Link"/>
            <body name="R_elbow_Link" pos="0 0.01 0.173" quat="0.500000 0.500000 0.500000 0.500000">
              <inertial pos="0.032625 0.007408 0.000111" quat="0.511664 0.505647 0.493594 0.48876" mass="0.24" diaginertia="0.00105837 0.001019 0.000141685"/>
<!--              <joint name="R_elbow" pos="0 0 0" axis="0 0 -1" range="0 1.5708" actuatorfrcrange="-14 14"/>-->
              <geom type="mesh" contype="0" conaffinity="0" group="1" density="0" rgba="1 1 1 1" mesh="R_elbow_Link"/>
            </body>
          </body>
        </body>
      </body>
      <body name="L_hip_yaw_Link" pos="0 0 -0.06">
        <inertial pos="0.000942 0.026834 -0.024386" quat="0.513117 0.858073 0.0197402 -0.0057536" mass="1.758" diaginertia="0.00499014 0.00440486 0.00192288"/>
        <joint name="L_hip_yaw" pos="0 0 0" axis="0 0 1" range="-0.785398 0.785398" armature="0.0807" damping='0.5' limited='true'/>
        <geom type="mesh" contype="0" conaffinity="0" group="1" density="0" rgba="0.898039 0.917647 0.929412 1" mesh="L_hip_yaw_Link"/>
        <body name="L_hip_roll_Link" pos="0 0.09 -0.0474" quat="0 0.707107 0 -0.707107">
          <inertial pos="0.066798 -0.001559 0.021277" quat="0.50932 0.472466 0.565401 0.444624" mass="1.562" diaginertia="0.00442533 0.00416718 0.00298586"/>
          <joint name="L_hip_roll" pos="0 0 0" axis="0 0 -1" range="-0.261799 0.785398" armature="0.0807" damping='0.5' limited='true'/>
          <geom type="mesh" contype="0" conaffinity="0" group="1" density="0" rgba="0.898039 0.917647 0.929412 1" mesh="L_hip_roll_Link"/>
          <body name="L_hip_pitch_Link" pos="0.092 -0.001 -2.97933e-05" quat="0.707107 -0.707107 0 0">
            <inertial pos="0.082779 -0.000893 -0.001942" quat="0.501001 0.496721 0.511125 0.490936" mass="1.332" diaginertia="0.0171659 0.0170279 0.000932154"/>
            <joint name="L_hip_pitch" pos="0 0 0" axis="0 0 1" range="-0.523599 2.00713" armature="0.0807" damping='0.5' limited='true'/>
            <geom type="mesh" contype="0" conaffinity="0" group="1" density="0" rgba="1 1 1 1" mesh="L_hip_pitch_Link"/>
            <body name="L_knee_Link" pos="0.35 -2.97933e-05 0">
              <inertial pos="0.126574 0.002525 -0.000118" quat="-0.0104785 0.706909 0.0120787 0.707124" mass="0.847" diaginertia="0.010827 0.0106712 0.00379418"/>
              <joint name="L_knee_pitch" pos="0 0 0" axis="0 0 1" range="-2.44346 0.0872665" armature="0.0807" damping='0.5' limited='true'/>
              <geom type="mesh" contype="0" conaffinity="0" group="1" density="0" rgba="0.419608 0.419608 0.419608 1" mesh="L_knee_Link"/>
              <body name="L_ankle_pitch_Link" pos="0.35 0 0">
                <inertial pos="0.027322 0.011889 -0.000237" quat="0.487322 0.518113 -0.480787 0.512757" mass="0.256" diaginertia="0.000981359 0.000891022 0.000132689"/>
                <joint name="L_ankle_pitch" pos="0 0 0" axis="0 0 1" range="-1.39626 1.0472" armature="0.0807" damping='0.5' limited='true'/>
                <geom type="mesh" contype="0" conaffinity="0" group="1" density="0" rgba="1 1 1 1" mesh="L_ankle_pitch_Link"/>
                <geom type="mesh" mesh="L_ankle_pitch_Link" class='collision-left'/>
              </body>
            </body>
          </body>
        </body>
      </body>
      <body name="R_hip_yaw_Link" pos="0 0 -0.1074">
        <inertial pos="0.001115 -0.049187 0.001444" quat="0.711805 0.702146 0.00130777 -0.0179453" mass="0.907" diaginertia="0.00206787 0.00201677 0.000566621"/>
        <joint name="R_hip_yaw" pos="0 0 0" axis="0 0 -1" range="-0.785398 0.785398" armature="0.0807" damping='0.5' limited='true'/>
        <geom type="mesh" contype="0" conaffinity="0" group="1" density="0" rgba="0.898039 0.917647 0.929412 1" mesh="R_hip_yaw_Link"/>
        <body name="R_hip_roll_Link" pos="0 -0.09 0" quat="0.707107 0 0.707107 0">
          <inertial pos="0.066798 -0.001559 -0.021277" quat="0.472466 0.50932 0.444624 0.565401" mass="1.562" diaginertia="0.00442533 0.00416718 0.00298586"/>
          <joint name="R_hip_roll" pos="0 0 0" axis="0 0 -1" range="-0.261799 0.785398" armature="0.0807" damping='0.5' limited='true'/>
          <geom type="mesh" contype="0" conaffinity="0" group="1" density="0" rgba="1 1 1 1" mesh="R_hip_roll_Link"/>
          <body name="R_hip_pitch_Link" pos="0.092 -0.001 2.97933e-05" quat="0.707107 -0.707107 0 0">
            <inertial pos="0.082779 0.000893 -0.001942" quat="0.502748 0.499246 0.49272 0.505197" mass="1.332" diaginertia="0.0171659 0.0170279 0.000932154"/>
            <joint name="R_hip_pitch" pos="0 0 0" axis="0 0 -1" range="-0.523599 2.00713" armature="0.0807" damping='0.5' limited='true'/>
            <geom type="mesh" contype="0" conaffinity="0" group="1" density="0" rgba="1 1 1 1" mesh="R_hip_pitch_Link"/>
            <body name="R_knee_Link" pos="0.35 2.97933e-05 0">
              <inertial pos="0.126574 -0.002525 -0.000118" quat="0.0107495 0.707104 -0.0118079 0.70693" mass="0.847" diaginertia="0.010827 0.0106712 0.00379418"/>
              <joint name="R_knee_pitch" pos="0 0 0" axis="0 0 -1" range="-2.44346 0.0872665" armature="0.0807" damping='0.5' limited='true'/>
              <geom type="mesh" contype="0" conaffinity="0" group="1" density="0" rgba="0.419608 0.419608 0.419608 1" mesh="R_knee_Link"/>
              <body name="R_ankle_pitch_Link" pos="0.35 0 0">
                <inertial pos="0.027322 -0.011889 -0.000237" quat="0.512559 0.48148 -0.51832 0.486625" mass="0.256" diaginertia="0.000981357 0.000891024 0.000132688"/>
                <joint name="R_ankle_pitch" pos="0 0 0" axis="0 0 -1" range="-1.39626 1.0472" armature="0.0807" damping='0.5' limited='true'/>
                <geom type="mesh" contype="0" conaffinity="0" group="1" density="0" rgba="1 1 1 1" mesh="R_ankle_pitch_Link"/>
                <geom type="mesh" mesh="R_ankle_pitch_Link" class='collision-right'/>
              </body>
            </body>
          </body>
        </body>
      </body>
    </body>
  </worldbody>

  <actuator>
<!--    <motor name="jpL" joint="L_shoulder_pitch" gear="1.00" ctrlrange="-300.0 300.0" ctrllimited="true"/>  Arm Left -->
<!--    <motor name="jrL" joint="L_shoulder_roll"  gear="1.00" ctrlrange="-300.0 300.0" ctrllimited="true"/>-->
<!--    <motor name="jyL" joint="L_shoulder_yaw"   gear="1.00" ctrlrange="-300.0 300.0" ctrllimited="true"/>-->
<!--    <motor name="jeL" joint="L_elbow"          gear="1.00" ctrlrange="-300.0 300.0" ctrllimited="true"/>-->

<!--    <motor name="jpR" joint="R_shoulder_pitch" gear="1.00" ctrlrange="-300.0 300.0" ctrllimited="true"/>  Arm Right-->
<!--    <motor name="jrR" joint="R_shoulder_roll"  gear="1.00" ctrlrange="-300.0 300.0" ctrllimited="true"/>-->
<!--    <motor name="jyR" joint="R_shoulder_yaw"   gear="1.00" ctrlrange="-300.0 300.0" ctrllimited="true"/>-->
<!--    <motor name="jeR" joint="R_elbow"          gear="1.00" ctrlrange="-300.0 300.0" ctrllimited="true"/>-->

    <motor name="juL" joint="L_hip_yaw"       gear="1.00" ctrlrange="-300.0 300.0" ctrllimited="true"/> <!-- Leg Left -->
    <motor name="jsL" joint="L_hip_roll"      gear="1.00" ctrlrange="-300.0 300.0" ctrllimited="true"/>
    <motor name="jhL" joint="L_hip_pitch"     gear="1.00" ctrlrange="-300.0 300.0" ctrllimited="true"/>
    <motor name="jkL" joint="L_knee_pitch"    gear="1.00" ctrlrange="-300.0 300.0" ctrllimited="true"/>
    <motor name="jFL" joint="L_ankle_pitch"   gear="1.00" ctrlrange="-300.0 300.0" ctrllimited="true"/>

    <motor name="juR" joint="R_hip_yaw"       gear="1.00" ctrlrange="-300.0 300.0" ctrllimited="true"/> <!-- Leg Right -->
    <motor name="jsR" joint="R_hip_roll"      gear="1.00" ctrlrange="-300.0 300.0" ctrllimited="true"/>
    <motor name="jhR" joint="R_hip_pitch"     gear="1.00" ctrlrange="-300.0 300.0" ctrllimited="true"/>
    <motor name="jkR" joint="R_knee_pitch"    gear="1.00" ctrlrange="-300.0 300.0" ctrllimited="true"/>
    <motor name="jFR" joint="R_ankle_pitch"   gear="1.00" ctrlrange="-300.0 300.0" ctrllimited="true"/>
  </actuator>

  <sensor>
    <!-- 执行器的位置 -->
<!--    <jointpos name="jpLp" joint="L_shoulder_pitch" noise="0.0"/>  Arm Left-->
<!--    <jointpos name="jrLp" joint="L_shoulder_roll"  noise="0.0"/>-->
<!--    <jointpos name="jyLp" joint="L_shoulder_yaw"   noise="0.0"/>-->
<!--    <jointpos name="jeLp" joint="L_elbow"          noise="0.0"/>-->

<!--    <jointpos name="jpRp" joint="R_shoulder_pitch" noise="0.0"/> Arm Right-->
<!--    <jointpos name="jrRp" joint="R_shoulder_roll"  noise="0.0"/>-->
<!--    <jointpos name="jyRp" joint="R_shoulder_yaw"   noise="0.0"/>-->
<!--    <jointpos name="jeRp" joint="R_elbow"          noise="0.0"/>-->

    <jointpos name="juLp" joint="L_hip_yaw"        noise="0.0"/> <!-- Leg Left -->
    <jointpos name="jsLp" joint="L_hip_roll"       noise="0.0"/>
    <jointpos name="jhLp" joint="L_hip_pitch"      noise="0.0"/>
    <jointpos name="jkLp" joint="L_knee_pitch"     noise="0.0"/>
    <jointpos name="jFLp" joint="L_ankle_pitch"    noise="0.0"/>

    <jointpos name="juRp" joint="R_hip_yaw"        noise="0.0"/> <!-- Leg Right -->
    <jointpos name="jsRp" joint="R_hip_roll"       noise="0.0"/>
    <jointpos name="jhRp" joint="R_hip_pitch"      noise="0.0"/>
    <jointpos name="jkRp" joint="R_knee_pitch"     noise="0.0"/>
    <jointpos name="jFRp" joint="R_ankle_pitch"    noise="0.0"/>

    <!-- 执行器的速度 -->
<!--    <jointvel name="jpLv" joint="L_shoulder_pitch" noise="0.0"/> Arm Left-->
<!--    <jointvel name="jrLv" joint="L_shoulder_roll"  noise="0.0"/>-->
<!--    <jointvel name="jyLv" joint="L_shoulder_yaw"   noise="0.0"/>-->
<!--    <jointvel name="jeLv" joint="L_elbow"          noise="0.0"/>-->

<!--    <jointvel name="jpRv" joint="R_shoulder_pitch" noise="0.0"/> Arm Right-->
<!--    <jointvel name="jrRv" joint="R_shoulder_roll"  noise="0.0"/>-->
<!--    <jointvel name="jyRv" joint="R_shoulder_yaw"   noise="0.0"/>-->
<!--    <jointvel name="jeRv" joint="R_elbow"          noise="0.0"/>-->

    <jointvel name="juLv" joint="L_hip_yaw"        noise="0.0"/> <!-- Leg Left -->
    <jointvel name="jsLv" joint="L_hip_roll"       noise="0.0"/>
    <jointvel name="jhLv" joint="L_hip_pitch"      noise="0.0"/>
    <jointvel name="jkLv" joint="L_knee_pitch"     noise="0.0"/>
    <jointvel name="jFLv" joint="L_ankle_pitch"    noise="0.0"/>

    <jointvel name="juRv" joint="R_hip_yaw"        noise="0.0"/> <!-- Leg Right -->
    <jointvel name="jsRv" joint="R_hip_roll"       noise="0.0"/>
    <jointvel name="jhRv" joint="R_hip_pitch"      noise="0.0"/>
    <jointvel name="jkRv" joint="R_knee_pitch"     noise="0.0"/>
    <jointvel name="jFRv" joint="R_ankle_pitch"    noise="0.0"/>

    <!-- 执行器的扭矩电流 -->
<!--    <actuatorfrc name="ipL" actuator="jpL" noise="0.0"/>  Arm Left-->
<!--    <actuatorfrc name="irL" actuator="jrL" noise="0.0"/>-->
<!--    <actuatorfrc name="iyL" actuator="jyL" noise="0.0"/>-->
<!--    <actuatorfrc name="ieL" actuator="jeL" noise="0.0"/>-->

<!--    <actuatorfrc name="ipR" actuator="jpR" noise="0.0"/> Arm Right-->
<!--    <actuatorfrc name="irR" actuator="jrR" noise="0.0"/>-->
<!--    <actuatorfrc name="iyR" actuator="jyR" noise="0.0"/>-->
<!--    <actuatorfrc name="ieR" actuator="jeR" noise="0.0"/>-->

    <actuatorfrc name="iuL" actuator="juL" noise="0.0"/> <!-- Leg Left -->
    <actuatorfrc name="isL" actuator="jsL" noise="0.0"/>
    <actuatorfrc name="ihL" actuator="jhL" noise="0.0"/>
    <actuatorfrc name="ikL" actuator="jkL" noise="0.0"/>
    <actuatorfrc name="iFL" actuator="jFL" noise="0.0"/>

    <actuatorfrc name="iuR" actuator="juR" noise="0.0"/> <!-- Leg Right -->
    <actuatorfrc name="isR" actuator="jsR" noise="0.0"/>
    <actuatorfrc name="ihR" actuator="jhR" noise="0.0"/>
    <actuatorfrc name="ikR" actuator="jkR" noise="0.0"/>
    <actuatorfrc name="iFR" actuator="jFR" noise="0.0"/>

    <!-- 身体的的姿态 -->
    <gyro          name="gyro"    site='imu' noise='0.005' cutoff='34.9'/>
    <accelerometer name="acc"     site='imu' noise='0.005' cutoff='157'/>
    <framequat     name='bq'      objtype='site' noise='0.001' objname='imu'/>
  </sensor>
</mujoco>
