<?xml version="1.0" encoding="utf-8"?>
<!-- This URDF was automatically created by SolidWorks to URDF Exporter! Originally created by Stephen Brawner (brawner@gmail.com) 
     Commit Version: 1.6.0-4-g7f85cfe  Build Version: 1.6.7995.38578
     For more information, please see http://wiki.ros.org/sw_urdf_exporter -->
<robot name="X02Lite">
  <mujoco>
    <compiler meshdir="meshes" discardvisual="false"/>
  </mujoco>
  <!-- [CAUTION] uncomment when convert to mujoco -->
  <link name="world"></link>
  <joint name="pelvis" type="floating">
    <parent link="world"/>
    <child link="pelvis"/>
  </joint>

  <link name="pelvis">
    <inertial>
      <origin xyz="-0.0000717 0.0001443 -0.0195866" rpy="0 0 0" />
      <mass value="0.5786" />
      <inertia ixx="0.0004533504" ixy="-0.0000000581" ixz="-0.0000006777" iyy="0.0004080524" iyz="0.0000027471" izz="0.0005122071" />
    </inertial>
    <visual>
      <origin xyz="0 0 0" rpy="0 0 0" />
      <geometry>
        <mesh filename="meshes/pelvis.STL" />
      </geometry>
      <material name="">
        <color rgba="1 1 1 1" />
      </material>
    </visual>
    <!-- <collision> -->
    <origin xyz="0 0 0" rpy="0 0 0" />
    <geometry>
      <mesh filename="meshes/pelvis.STL" />
    </geometry>
    <!-- </collision> -->
  </link>
  <link name="L_hip_yaw_Link">
    <inertial>
      <origin xyz="0.000942 0.026834 -0.024386" rpy="0 0 0" />
      <mass value="1.758" />
      <inertia ixx="0.004988888" ixy="0.000039059" ixz="-0.000005421" iyy="0.002479734" iyz="-0.001035324" izz="0.003849267" />
    </inertial>
    <visual>
      <origin xyz="0 0 0" rpy="0 0 0" />
      <geometry>
        <mesh filename="meshes/L_hip_yaw_Link.STL" />
      </geometry>
      <material name="">
        <color rgba="0.898039215686275 0.917647058823529 0.929411764705882 1" />
      </material>
    </visual>
    <!-- <collision> -->
    <origin xyz="0 0 0" rpy="0 0 0" />
    <geometry>
      <mesh filename="meshes/L_hip_yaw_Link.STL" />
    </geometry>
    <!-- </collision> -->
  </link>
  <joint name="L_hip_yaw" type="revolute">
    <origin xyz="0 0 -0.06" rpy="0 0 0" />
    <parent link="pelvis" />
    <child link="L_hip_yaw_Link" />
    <axis xyz="0 0 1" />
    <limit lower="-0.7853981633974483" upper="0.7853981633974483" effort="50" velocity="10.471975511965978"/>
  </joint>
  <link name="L_hip_roll_Link">
    <inertial>
      <origin xyz="0.066798 -0.001559 0.021277" rpy="0 0 0" />
      <mass value="1.562" />
      <inertia ixx="0.002995411" ixy="-0.000034162" ixz="0.000102364" iyy="0.004418205" iyz="-0.000037524" izz="0.004164746" />
    </inertial>
    <visual>
      <origin xyz="0 0 0" rpy="0 0 0" />
      <geometry>
        <mesh filename="meshes/L_hip_roll_Link.STL" />
      </geometry>
      <material name="">
        <color rgba="0.898039215686275 0.917647058823529 0.929411764705882 1" />
      </material>
    </visual>
    <!-- <collision> -->
    <origin xyz="0 0 0" rpy="0 0 0" />
    <geometry>
      <mesh filename="meshes/L_hip_roll_Link.STL" />
    </geometry>
    <!-- </collision> -->
  </link>
  <joint name="L_hip_roll" type="revolute">
    <origin xyz="0 0.09 -0.0474" rpy="3.14159265358979 1.5707963267949 0" />
    <parent link="L_hip_yaw_Link" />
    <child link="L_hip_roll_Link" />
    <axis xyz="0 0 -1" />
    <limit lower="-0.2617993877991494" upper="0.7853981633974483" effort="50" velocity="10.471975511965978"/>
  </joint>
  <link name="L_hip_pitch_Link">
    <inertial>
      <origin xyz="0.082779 -0.000893 -0.001942" rpy="0 0 0" />
      <mass value="1.332" />
      <inertia ixx="0.000936533" ixy="-0.000067319" ixz="0.000256852" iyy="0.017165588" iyz="-0.000002308" izz="0.017023851" />
    </inertial>
    <visual>
      <origin xyz="0 0 0" rpy="0 0 0" />
      <geometry>
        <mesh filename="meshes/L_hip_pitch_Link.STL" />
      </geometry>
      <material name="">
        <color rgba="1 1 1 1" />
      </material>
    </visual>
    <!-- <collision> -->
    <origin xyz="0 0 0" rpy="0 0 0" />
    <geometry>
      <mesh filename="meshes/L_hip_pitch_Link.STL" />
    </geometry>
    <!-- </collision> -->
  </link>
  <joint name="L_hip_pitch" type="revolute">
    <origin xyz="0.092 -0.001 -2.97932823952292E-05" rpy="-1.5707963267949 0 0" />
    <parent link="L_hip_roll_Link" />
    <child link="L_hip_pitch_Link" />
    <axis xyz="0 0 1" />
    <limit lower="-0.5235987755982988" upper="2.007128639793479" effort="72" velocity="9.16297857297023"/>
  </joint>
  <link name="L_knee_Link">
    <inertial>
      <origin xyz="0.126574 0.002525 -0.000118" rpy="0 0 0" />
      <mass value="0.847" />
      <inertia ixx="0.003801179" ixy="-0.000219244" ixz="-0.000001892" iyy="0.010664214" iyz="0.000000293" izz="0.010826971" />
    </inertial>
    <visual>
      <origin xyz="0 0 0" rpy="0 0 0" />
      <geometry>
        <mesh filename="meshes/L_knee_Link.STL" />
      </geometry>
      <material name="">
        <color rgba="0.419607843137255 0.419607843137255 0.419607843137255 1" />
      </material>
    </visual>
    <!-- <collision> -->
    <origin xyz="0 0 0" rpy="0 0 0" />
    <geometry>
      <mesh filename="meshes/L_knee_Link.STL" />
    </geometry>
    <!-- </collision> -->
  </link>
  <joint name="L_knee_pitch" type="revolute">
    <origin xyz="0.349999998731943 -2.9793282395241E-05 0" rpy="0 0 0" />
    <parent link="L_hip_pitch_Link" />
    <child link="L_knee_Link" />
    <axis xyz="0 0 1" />
    <limit lower="-2.443460952792061" upper="0.08726646259971647" effort="150" velocity="7.3303828583761845"/>
  </joint>
  <link name="L_ankle_pitch_Link">
    <inertial>
      <origin xyz="0.027322 0.011889 -0.000237" rpy="0 0 0" />
      <mass value="0.256" />
      <inertia ixx="0.000888050" ixy="0.000047483" ixz="0.000001032" iyy="0.000135674" iyz="0.000000750" izz="0.000981346" />
    </inertial>
    <visual>
      <origin xyz="0 0 0" rpy="0 0 0" />
      <geometry>
        <mesh filename="meshes/L_ankle_pitch_Link.STL" />
      </geometry>
      <material name="">
        <color rgba="1 1 1 1" />
      </material>
    </visual>
    <collision>
      <origin xyz="0.041 0.02 0" rpy="1.5707963267948966 0 0" />
      <geometry>
        <!-- <mesh --> filename="meshes/L_ankle_pitch_Link.STL" />
        <cylinder length="0.249" radius="0.018" />
      </geometry>
    </collision>
  </link>
  <joint name="L_ankle_pitch" type="revolute">
    <origin xyz="0.35 0 0" rpy="0 0 0" />
    <parent link="L_knee_Link" />
    <child link="L_ankle_pitch_Link" />
    <axis xyz="0 0 1" />
    <limit lower="-1.3962634015954636" upper="1.0471975511965976" effort="45" velocity="14.660765716752369"/>
  </joint>
  <link name="R_hip_yaw_Link">
    <inertial>
      <origin xyz="0.001115 -0.049187 0.001444" rpy="0 0 0" />
      <mass value="0.907" />
      <inertia ixx="0.002067018" ixy="-0.000035043" ixz="-0.000000909" iyy="0.000567723" iyz="0.000020295" izz="0.002016525" />
    </inertial>
    <visual>
      <origin xyz="0 0 0" rpy="0 0 0" />
      <geometry>
        <mesh filename="meshes/R_hip_yaw_Link.STL" />
      </geometry>
      <material name="">
        <color rgba="0.898039215686275 0.917647058823529 0.929411764705882 1" />
      </material>
    </visual>
    <!-- <collision> -->
    <origin xyz="0 0 0" rpy="0 0 0" />
    <geometry>
      <mesh filename="meshes/R_hip_yaw_Link.STL" />
    </geometry>
    <!-- </collision> -->
  </link>
  <joint name="R_hip_yaw" type="revolute">
    <origin xyz="0 0 -0.1074" rpy="0 0 0" />
    <parent link="pelvis" />
    <child link="R_hip_yaw_Link" />
    <axis xyz="0 0 -1" />
    <limit lower="-0.7853981633974483" upper="0.7853981633974483" effort="50" velocity="10.471975511965978"/>
  </joint>
  <link name="R_hip_roll_Link">
    <inertial>
      <origin xyz="0.066798 -0.001559 -0.021277" rpy="0 0 0" />
      <mass value="1.562" />
      <inertia ixx="0.002995411" ixy="-0.000034162" ixz="-0.000102364" iyy="0.004418205" iyz="0.000037524" izz="0.004164746" />
    </inertial>
    <visual>
      <origin xyz="0 0 0" rpy="0 0 0" />
      <geometry>
        <mesh filename="meshes/R_hip_roll_Link.STL" />
      </geometry>
      <material name="">
        <color rgba="1 1 1 1" />
      </material>
    </visual>
    <!-- <collision> -->
    <origin xyz="0 0 0" rpy="0 0 0" />
    <geometry>
      <mesh filename="meshes/R_hip_roll_Link.STL" />
    </geometry>
    <!-- </collision> -->
  </link>
  <joint name="R_hip_roll" type="revolute">
    <origin xyz="0 -0.09 0" rpy="0 1.5707963267949 0" />
    <parent link="R_hip_yaw_Link" />
    <child link="R_hip_roll_Link" />
    <axis xyz="0 0 -1" />
    <limit lower="-0.2617993877991494" upper="0.7853981633974483" effort="50" velocity="10.471975511965978"/>
  </joint>
  <link name="R_hip_pitch_Link">
    <inertial>
      <origin xyz="0.082779 0.000893 -0.001942" rpy="0 0 0" />
      <mass value="1.332" />
      <inertia ixx="0.000936533" ixy="0.000067319" ixz="-0.000256852" iyy="0.017165588" iyz="0.000002308" izz="0.017023851" />
    </inertial>
    <visual>
      <origin xyz="0 0 0" rpy="0 0 0" />
      <geometry>
        <mesh filename="meshes/R_hip_pitch_Link.STL" />
      </geometry>
      <material name="">
        <color rgba="1 1 1 1" />
      </material>
    </visual>
    <!-- <collision> -->
    <origin xyz="0 0 0" rpy="0 0 0" />
    <geometry>
      <mesh filename="meshes/R_hip_pitch_Link.STL" />
    </geometry>
    <!-- </collision> -->
  </link>
  <joint name="R_hip_pitch" type="revolute">
    <origin xyz="0.092 -0.00100000000000001 2.97932823952229E-05" rpy="-1.5707963267949 0 0" />
    <parent link="R_hip_roll_Link" />
    <child link="R_hip_pitch_Link" />
    <axis xyz="0 0 -1" />
    <limit lower="-0.5235987755982988" upper="2.007128639793479" effort="72" velocity="9.16297857297023"/>
  </joint>
  <link name="R_knee_Link">
    <inertial>
      <origin xyz="0.126574 -0.002525 -0.000118" rpy="0 0 0" />
      <mass value="0.847" />
      <inertia ixx="0.003801179" ixy="0.000219244" ixz="0.000001892" iyy="0.010664214" iyz="-0.000000293" izz="0.010826971" />
    </inertial>
    <visual>
      <origin xyz="0 0 0" rpy="0 0 0" />
      <geometry>
        <mesh filename="meshes/R_knee_Link.STL" />
      </geometry>
      <material name="">
        <color rgba="0.419607843137255 0.419607843137255 0.419607843137255 1" />
      </material>
    </visual>
    <!-- <collision> -->
    <origin xyz="0 0 0" rpy="0 0 0" />
    <geometry>
      <mesh filename="meshes/R_knee_Link.STL" />
    </geometry>
    <!-- </collision> -->
  </link>
  <joint name="R_knee_pitch" type="revolute">
    <origin xyz="0.349999998731943 2.97932823952059E-05 0" rpy="0 0 0" />
    <parent link="R_hip_pitch_Link" />
    <child link="R_knee_Link" />
    <axis xyz="0 0 -1" />
    <limit lower="-2.443460952792061" upper="0.08726646259971647" effort="150" velocity="7.3303828583761845"/>
  </joint>
  <link name="R_ankle_pitch_Link">
    <inertial>
      <origin xyz="0.027322 -0.011889 -0.000237" rpy="0 0 0" />
      <mass value="0.256" />
      <inertia ixx="0.000888050" ixy="-0.000047483" ixz="-0.000001032" iyy="0.000135674" iyz="-0.000000750" izz="0.000981346" />
    </inertial>
    <visual>
      <origin xyz="0 0 0" rpy="0 0 0" />
      <geometry>
        <mesh filename="meshes/R_ankle_pitch_Link.STL" />
      </geometry>
      <material name="">
        <color rgba="1 1 1 1" />
      </material>
    </visual>
    <collision>
      <origin xyz="0.041 -0.02 0" rpy="1.5707963267948966 0 0" />
      <geometry>
        <!-- <mesh --> filename="meshes/R_ankle_pitch_Link.STL" />
        <cylinder length="0.249" radius="0.018"/>
      </geometry>
    </collision>
  </link>
  <joint name="R_ankle_pitch" type="revolute">
    <origin xyz="0.35 0 0" rpy="0 0 0" />
    <parent link="R_knee_Link" />
    <child link="R_ankle_pitch_Link" />
    <axis xyz="0 0 -1" />
    <limit lower="-1.3962634015954636" upper="1.0471975511965976" effort="45" velocity="14.660765716752369"/>
  </joint>
  <link name="torso_Link">
    <inertial>
      <origin xyz="0.0031437 0.0003242 0.1851956" rpy="0 0 0" />
      <mass value="9.2618" />
      <inertia ixx="0.1425570539" ixy="-0.0002470731" ixz="-0.0010896186" iyy="0.1131721333" iyz="0.0002687928" izz="0.0741723374" />
    </inertial>
    <visual>
      <origin xyz="0 0 0" rpy="0 0 0" />
      <geometry>
        <mesh filename="meshes/torso_link.STL" />
      </geometry>
      <material name="">
        <color rgba="1 1 1 1" />
      </material>
    </visual>
    <!-- <collision> -->
    <origin xyz="0 0 0" rpy="0 0 0" />
    <geometry>
      <mesh filename="meshes/torso_link.STL" />
    </geometry>
    <!-- </collision> -->
  </link>
  <joint name="torso" type="fixed">
    <origin xyz="0 0 0" rpy="0 0 0" />
    <parent link="pelvis" />
    <child link="torso_Link" />
    <axis xyz="0 0 1" />
    <limit lower="-0.785" upper="0.785" effort="50" velocity="10.471975511965978"/>
  </joint>
  <link name="L_shoulder_pitch_Link">
    <inertial>
      <origin xyz="0.000994 0.000135 0.015061" rpy="0 0 0" />
      <mass value="0.3" />
      <inertia ixx="0.000621497" ixy="-0.000000128" ixz="0.000008777" iyy="0.000564556" iyz="0.000001116" izz="0.000170804" />
    </inertial>
    <visual>
      <origin xyz="0 0 0" rpy="0 0 0" />
      <geometry>
        <mesh filename="meshes/L_shoulder_pitch_Link.STL" />
      </geometry>
      <material name="">
        <color rgba="0.2 0.2 0.2 0.9" />
      </material>
    </visual>
    <!-- <collision> -->
    <origin xyz="0 0 0" rpy="0 0 0" />
    <geometry>
      <mesh filename="meshes/L_shoulder_pitch_Link.STL" />
    </geometry>
    <!-- </collision> -->
  </link>
  <joint name="L_shoulder_pitch" type="fixed">
    <origin xyz="0 0.136078524596347 0.306812038248655" rpy="0 1.30899693899577 1.5707963267949" />
    <parent link="torso_Link" />
    <child link="L_shoulder_pitch_Link" />
    <axis xyz="0 0 -1" />
    <limit lower="-1.5707963267948966" upper="3.141592653589793" effort="18" velocity="5.235987755982989"/>
  </joint>
  <link name="L_shoulder_roll_Link">
    <inertial>
      <origin xyz="0.043319 -0.000273 0.000056" rpy="0 0 0" />
      <mass value="0.704" />
      <inertia ixx="0.000295478" ixy="-0.000008088" ixz="-0.000005229" iyy="0.001502613" iyz="0.000000085" izz="0.001450385" />
    </inertial>
    <visual>
      <origin xyz="0 0 0" rpy="0 0 0" />
      <geometry>
        <mesh filename="meshes/L_shoulder_roll_Link.STL" />
      </geometry>
      <material name="">
        <color rgba="1 1 1 1" />
      </material>
    </visual>
    <!-- <collision> -->
    <origin xyz="0 0 0" rpy="0 0 0" />
    <geometry>
      <mesh filename="meshes/L_shoulder_roll_Link.STL" />
    </geometry>
    <!-- </collision> -->
  </link>
  <joint name="L_shoulder_roll" type="fixed">
    <origin xyz="0 0 0.0609999999999959" rpy="-1.5707963267949 0.261799387799122 0" />
    <parent link="L_shoulder_pitch_Link" />
    <child link="L_shoulder_roll_Link" />
    <axis xyz="0 0 -1" />
    <limit lower="0.0" upper="3.141592653589793" effort="14" velocity="5.235987755982989"/>
  </joint>
  <link name="L_shoulder_yaw_Link">
    <inertial>
      <origin xyz="0.000230 -0.004330 0.132049" rpy="0 0 0" />
      <mass value="0.523" />
      <inertia ixx="0.002033687" ixy="0.000000601" ixz="0.000003592" iyy="0.002073388" iyz="-0.000141088" izz="0.000293100" />
    </inertial>
    <visual>
      <origin xyz="0 0 0" rpy="0 0 0" />
      <geometry>
        <mesh filename="meshes/L_shoulder_yaw_Link.STL" />
      </geometry>
      <material name="">
        <color rgba="0.2 0.2 0.2 0.9" />
      </material>
    </visual>
    <!-- <collision> -->
    <origin xyz="0 0 0" rpy="0 0 0" />
    <geometry>
      <mesh filename="meshes/L_shoulder_yaw_Link.STL" />
    </geometry>
    <!-- </collision> -->
  </link>
  <joint name="L_shoulder_yaw" type="fixed">
    <origin xyz="0.112 0 0" rpy="1.57079632679458 0 1.5707963267949" />
    <parent link="L_shoulder_roll_Link" />
    <child link="L_shoulder_yaw_Link" />
    <axis xyz="0 0 -1" />
    <limit lower="-2.2689280275926285" upper="2.2689280275926285" effort="14" velocity="5.235987755982989"/>
  </joint>
  <link name="L_elbow_Link">
    <inertial>
      <origin xyz="0.032629 -0.007406 0.000107" rpy="0 0 0" />
      <mass value="0.24" />
      <inertia ixx="0.000142806" ixy="-0.000032013" ixz="-0.000001218" iyy="0.001057248" iyz="0.000000384" izz="0.001019002" />
    </inertial>
    <visual>
      <origin xyz="0 0 0" rpy="0 0 0" />
      <geometry>
        <mesh filename="meshes/L_elbow_Link.STL" />
      </geometry>
      <material name="">
        <color rgba="1 1 1 1" />
      </material>
    </visual>
    <!-- <collision> -->
    <origin xyz="0 0 0" rpy="0 0 0" />
    <geometry>
      <mesh filename="meshes/L_elbow_Link.STL" />
    </geometry>
    <!-- </collision> -->
  </link>
  <joint name="L_elbow" type="fixed">
    <origin xyz="0 -0.0100000000001793 0.172999999999993" rpy="1.5707963267949 3.1416 1.5707963267949" />
    <parent link="L_shoulder_yaw_Link" />
    <child link="L_elbow_Link" />
    <axis xyz="0 0 1" />
    <limit lower="0.0" upper="2.5307274153917776" effort="14" velocity="5.235987755982989"/>
  </joint>
  <link name="R_shoulder_pitch_Link">
    <inertial>
      <origin xyz="0.000994 -0.000135 0.015061" rpy="0 0 0" />
      <mass value="0.3" />
      <inertia ixx="0.000621496" ixy="0.000000130" ixz="0.000008777" iyy="0.000564553" iyz="-0.000001116" izz="0.000170801" />
    </inertial>
    <visual>
      <origin xyz="0 0 0" rpy="0 0 0" />
      <geometry>
        <mesh filename="meshes/R_shoulder_pitch_Link.STL" />
      </geometry>
      <material name="">
        <color rgba=".2 .2 .2 .9" />
      </material>
    </visual>
    <!-- <collision> -->
    <origin xyz="0 0 0" rpy="0 0 0" />
    <geometry>
      <mesh filename="meshes/R_shoulder_pitch_Link.STL" />
    </geometry>
    <!-- </collision> -->
  </link>
  <joint name="R_shoulder_pitch" type="fixed">
    <origin xyz="0 -0.136078524596347 0.306812038248655" rpy="0 1.30899693899578 -1.5707963267949" />
    <parent link="torso_Link" />
    <child link="R_shoulder_pitch_Link" />
    <axis xyz="0 0 1" />
    <limit lower="-1.5707963267948966" upper="3.141592653589793" effort="18" velocity="5.235987755982989"/>
  </joint>
  <link name="R_shoulder_roll_Link">
    <inertial>
      <origin xyz="0.043319 -0.000273 0.000056" rpy="0 0 0" />
      <mass value="0.704" />
      <inertia ixx="0.000295478" ixy="-0.000008088" ixz="0.000005229" iyy="0.001502613" iyz="0.000000085" izz="0.001450385" />
    </inertial>
    <visual>
      <origin xyz="0 0 0" rpy="0 0 0" />
      <geometry>
        <mesh filename="meshes/R_shoulder_roll_Link.STL" />
      </geometry>
      <material name="">
        <color rgba="1 1 1 1" />
      </material>
    </visual>
    <!-- <collision> -->
    <origin xyz="0 0 0" rpy="0 0 0" />
    <geometry>
      <mesh filename="meshes/R_shoulder_roll_Link.STL" />
    </geometry>
    <!-- </collision> -->
  </link>
  <joint name="R_shoulder_roll" type="fixed">
    <origin xyz="0 0 0.060999999999996" rpy="-1.5707963267949 0.261799387799122 0" />
    <parent link="R_shoulder_pitch_Link" />
    <child link="R_shoulder_roll_Link" />
    <axis xyz="0 0 -1" />
    <limit lower="-0.0" upper="3.141592653589793" effort="14" velocity="5.235987755982989"/>
  </joint>
  <link name="R_shoulder_yaw_Link">
    <inertial>
      <origin xyz="0.000230 0.004330 0.132049" rpy="0 0 0" />
      <mass value="0.523" />
      <inertia ixx="0.002033687" ixy="0.000000601" ixz="0.000003592" iyy="0.002073388" iyz="0.000141088" izz="0.000293100" />
    </inertial>
    <visual>
      <origin xyz="0 0 0" rpy="0 0 0" />
      <geometry>
        <mesh filename="meshes/R_shoulder_yaw_Link.STL" />
      </geometry>
      <material name="">
        <color rgba=".2 .2 .2 .9" />
      </material>
    </visual>
    <!-- <collision> -->
    <origin xyz="0 0 0" rpy="0 0 0" />
    <geometry>
      <mesh filename="meshes/R_shoulder_yaw_Link.STL" />
    </geometry>
    <!-- </collision> -->
  </link>
  <joint name="R_shoulder_yaw" type="fixed">
    <origin xyz="0.112 0 0" rpy="1.57079632679458 0 1.5707963267949" />
    <parent link="R_shoulder_roll_Link" />
    <child link="R_shoulder_yaw_Link" />
    <axis xyz="0 0 1" />
    <limit lower="-2.2689280275926285" upper="2.2689280275926285" effort="14" velocity="5.235987755982989"/>
  </joint>
  <link name="R_elbow_Link">
    <inertial>
      <origin xyz="0.032625 0.007408 0.000111" rpy="0 0 0" />
      <mass value="0.24" />
      <inertia ixx="0.000142806" ixy="0.000032013" ixz="-0.000001218" iyy="0.001057248" iyz="-0.000000384" izz="0.001019002" />
    </inertial>
    <visual>
      <origin xyz="0 0 0" rpy="0 0 0" />
      <geometry>
        <mesh filename="meshes/R_elbow_Link.STL" />
      </geometry>
      <material name="">
        <color rgba="1 1 1 1" />
      </material>
    </visual>
    <!-- <collision> -->
    <origin xyz="0 0 0" rpy="0 0 0" />
    <geometry>
      <mesh filename="meshes/R_elbow_Link.STL" />
    </geometry>
    <!-- </collision> -->
  </link>
  <joint name="R_elbow" type="fixed">
    <origin xyz="0 0.00999999999896754 0.173000000000008" rpy="1.5707963267949 0 1.5707963267949" />
    <parent link="R_shoulder_yaw_Link" />
    <child link="R_elbow_Link" />
    <axis xyz="0 0 -1" />
    <limit lower="0" upper="1.5707963267949" effort="14" velocity="5.235987755982989" />
  </joint>
  <link name="Head_Link">
    <inertial>
      <origin xyz="0.00948 0.001773 0.143409" rpy="0 0 0" />
      <mass value="1.177" />
      <inertia ixx="0.0071485868" ixy="-0.0000209215" ixz="-0.0000418265" iyy="0.0075081514" iyz="0.0000437403" izz="0.0052224569" />
    </inertial>
    <visual>
      <origin xyz="0 0 0" rpy="0 0 0" />
      <geometry>
        <mesh filename="meshes/Head_Link.STL" />
      </geometry>
      <material name="">
        <color rgba=".2 .2 .2 .9" />
      </material>
    </visual>
    <!-- <collision> -->
    <origin xyz="0 0 0" rpy="0 0 0" />
    <geometry>
      <mesh filename="meshes/Head_Link.STL" />
    </geometry>
    <!-- </collision> -->
  </link>
  <joint name="Head" type="fixed">
    <origin xyz="0 0 0.355" rpy="0 0 0" />
    <parent link="torso_Link" />
    <child link="Head_Link" />
    <axis xyz="0 0 0" />
  </joint>
  <link name="imu_link">
  </link>
  <joint name="imu_joint" type="fixed">
    <origin xyz="0 0 0.1625" rpy="0 0 0" />
    <parent link="torso_Link" />
    <child link="imu_link" />
  </joint>
  <link name="Logo_Link">
    <inertial>
      <origin xyz="0.082950590842835 0.000315079549949364 0.225243833498369" rpy="0 0 0" />
      <mass value="0.00512067879791543" />
      <inertia ixx="1.30394213485836E-06" ixy="-3.51341664144333E-11" ixz="4.09535398301672E-07" iyy="1.05676153928918E-06" iyz="5.51444099121383E-10" izz="9.50917700863864E-07" />
    </inertial>
    <visual>
      <origin xyz="0 0 0" rpy="0 0 0" />
      <geometry>
        <mesh filename="meshes/Logo_Link.STL" />
      </geometry>
      <material name="">
        <color rgba="1 0 0 .8" />
      </material>
    </visual>
    <!-- <collision> -->
    <origin xyz="0 0 0" rpy="0 0 0" />
    <geometry>
      <mesh filename="meshes/Logo_Link.STL" />
    </geometry>
    <!-- </collision> -->
  </link>
  <joint name="Logo" type="fixed">
    <origin xyz="0 0 0" rpy="0 0 0" />
    <parent link="torso_Link" />
    <child link="Logo_Link" />
    <axis xyz="0 0 0" />
  </joint>
</robot>